<?xml version="1.0"?>
<robot xmlns:xacro="http://www.ros.org/wiki/xacro">

	<!-- include other model components -->
	<xacro:include filename="$(find soft_hand_description)/model/materials.urdf.xacro"/>
	<xacro:include filename="$(find soft_hand_description)/model/soft_hand.transmission.xacro"/>
	<xacro:include filename="$(find soft_hand_description)/model/soft_hand.gazebo.xacro"/>
	<xacro:include filename="$(find soft_hand_description)/model/soft_hand.inertia.xacro"/>

	<!-- accesories -->
	<xacro:include filename="$(find soft_hand_description)/model/accesories/kuka_coupler.urdf.xacro"/>
	<xacro:include filename="$(find soft_hand_description)/model/accesories/clamp.urdf.xacro"/>
	<xacro:include filename="$(find soft_hand_description)/model/accesories/softhand_base.urdf.xacro"/>

	<!-- joint properties -->
	<xacro:property name="abd_lb" value="-30" />
	<xacro:property name="abd_ub" value="30" />
	<xacro:property name="thumb_abd_lb" value="0" />
	<xacro:property name="thumb_abd_ub" value="90" />
	<xacro:property name="inner_lb" value="0" />
	<xacro:property name="inner_ub" value="60" />
	<xacro:property name="middle_lb" value="0" />
	<xacro:property name="middle_ub" value="60" />
	<xacro:property name="outer_lb" value="0" />
	<xacro:property name="outer_ub" value="45" />
	<xacro:property name="velocity" value="100" />
	<xacro:property name="effort" value="10" />
	<xacro:property name="damping" value="0.0" />
	<xacro:property name="friction" value="0.0" />
	
	<!-- synergy joint properties -->
	<xacro:property name="synergy_lb" value="0.0" />
	<xacro:property name="synergy_ub" value="1.0"/>
	<xacro:property name="max_synergy_velocity" value="100000" />
	<xacro:property name="max_synergy_effort" value="100" />
	<xacro:property name="synergy_damping" value="0.0" />
	<xacro:property name="synergy_friction" value="0.0" />

	<xacro:property name="rubber_friction_coefficient" value="1.16" />  <!-- True: 1.16 -->
	<xacro:property name="rubber_contact_stiffness_coefficient" value="1000000.0" />
	<xacro:property name="rubber_contact_damping_coefficient" value="1.0" />

	<!-- SOFT FINGER model -->
	<!-- 4 fingers are equal (index, middle, ring, little) -->
	<xacro:macro name="soft_finger" params="parent parent_name name position orientation left">

		<!-- KNUCKLE -->
		<joint name="${name}_abd_joint" type="revolute">
			<origin xyz="${position}" rpy="${orientation}" />
			<parent link="${parent}"/>
			<child link="${name}_knuckle_link"/>
			<xacro:if value="${left}">
				<axis xyz="0 0 -1" />
			</xacro:if>
			<xacro:unless value="${left}">
				<axis xyz="0 0 1" />
			</xacro:unless>
			<limit lower="${abd_lb *pi/180}" upper="${abd_ub *pi/180}" effort="${effort}" velocity="${velocity}"/>
			<dynamics damping="${damping}" friction="${friction}"/>
		</joint>
		
		<link name="${name}_knuckle_link">
			<inertial>
				<xacro:insert_block name="knuckle_inertia"/>
			</inertial>
			<visual>
				<geometry>
					<mesh filename="package://soft_hand_description/meshes/knuckle.stl" scale=" .001 .001 .001" />
				</geometry>
				<material name="SoftHand/DarkGrey" />
			</visual>
			<collision>
				<geometry>
					<mesh filename="package://soft_hand_description/meshes/knuckle_collision.stl" scale=" .001 .001 .001" />
				</geometry>
			</collision>
		</link>
		<gazebo reference="${name}_knuckle_link">
			<material>Gazebo/Blue</material>
		</gazebo>

		<!-- PROXIMAL PHALANGE -->
		<joint name="${name}_inner_joint" type="revolute">
			<origin xyz="0.022 0 0" rpy="0 0 0" />
			<parent link="${name}_knuckle_link"/>
			<child link="${name}_proximal_link"/>
			<axis xyz="0 -1 0" />
			<limit lower="${inner_lb *pi/180}" upper="${inner_ub *pi/180}" effort="${effort}" velocity="${velocity}"/>
			<dynamics damping="${damping}" friction="${friction}"/>
		</joint>

		<link name="${name}_proximal_link">
			<inertial>
				<xacro:insert_block name="phalanx_inertia"/>
			</inertial>
			<visual>
				<geometry>
					<mesh filename="package://soft_hand_description/meshes/phalanx.stl" scale=" .001 .001 .001" />
				</geometry>
				<material name="SoftHand/DarkGrey" />
			</visual>
			<collision>
				<geometry>
					<mesh filename="package://soft_hand_description/meshes/phalanx_collision.stl" scale=" .001 .001 .001" />
				</geometry>
			</collision>
		</link>
		<gazebo reference="${name}_proximal_link">
			<material>Gazebo/Blue</material>
		</gazebo>

		<!-- MIDDLE PHALANGE -->
		<joint name="${name}_middle_joint" type="revolute">
			<origin xyz="0.022 0 0" rpy="0 0 0" />
			<parent link="${name}_proximal_link"/>
			<child link="${name}_middle_link"/>
			<axis xyz="0 -1 0" />
			<limit lower="${middle_lb *pi/180}" upper="${middle_ub *pi/180}" effort="${effort}" velocity="${velocity}"/>
			<dynamics damping="${damping}" friction="${friction}"/>
		</joint>

		<link name="${name}_middle_link">
			<inertial>
				<xacro:insert_block name="phalanx_inertia"/>
			</inertial>
			<visual>
				<geometry>
					<mesh filename="package://soft_hand_description/meshes/phalanx.stl" scale=" .001 .001 .001" />
				</geometry>
				<material name="SoftHand/DarkGrey" />
			</visual>
			<collision>
				<geometry>
					<mesh filename="package://soft_hand_description/meshes/phalanx_collision.stl" scale=" .001 .001 .001" />
				</geometry>
			</collision>
		</link>
		<gazebo reference="${name}_middle_link">
			<material>Gazebo/Blue</material>
		</gazebo>

		<!-- DISTAL PHALANGE -->
		<joint name="${name}_outer_joint" type="revolute">
			<origin xyz="0.022 0 0" rpy="0 0 0" />
			<parent link="${name}_middle_link"/>
			<child link="${name}_distal_link"/>
			<axis xyz="0 -1 0" />
			<limit lower="${outer_lb *pi/180}" upper="${outer_ub *pi/180}" effort="${effort}" velocity="${velocity}"/>
			<dynamics damping="${damping}" friction="${friction}"/>
		</joint>

		<link name="${name}_distal_link">
			<inertial>
				<xacro:insert_block name="fingertip_inertia"/>
			</inertial>
			<visual>
				<geometry>
					<mesh filename="package://soft_hand_description/meshes/fingertip.stl" scale=" .001 .001 .001" />
				</geometry>
				<material name="SoftHand/DarkGrey" />
			</visual>
			<collision>
				<geometry>
					<mesh filename="package://soft_hand_description/meshes/fingertip_collision.stl" scale=" .001 .001 .001" />
				</geometry>
			</collision>
		</link>
		<gazebo reference="${name}_distal_link">
			<selfCollide>false</selfCollide>
			<mu1>${rubber_friction_coefficient}</mu1>
			<mu2>${rubber_friction_coefficient}</mu2>
			<kp>${rubber_contact_stiffness_coefficient}</kp>
			<kd>${rubber_contact_damping_coefficient}</kd>
			<material>Gazebo/Blue</material>
		</gazebo>

	</xacro:macro>

	<!-- THUMB MODEL -->
	<!-- It has one joint less than rest of fingers -->
	<xacro:macro name="soft_thumb" params="parent parent_name name left position orientation">

		<xacro:if value="${left}">
			<!-- KNUCKLE -->
			<joint name="${name}_abd_joint" type="revolute">
				<origin xyz="${position}" rpy="${orientation}" />
				<parent link="${parent}"/>
				<child link="${name}_knuckle_link"/>
				<axis xyz="0 0 1" />
				<limit lower="${thumb_abd_lb *pi/180}" upper="${thumb_abd_ub *pi/180}" effort="${effort}" velocity="${velocity}"/>
				<dynamics damping="${damping}" friction="${friction}"/>
			</joint>
			
			<link name="${name}_knuckle_link">
				<inertial>
					<xacro:insert_block name="thumb_knuckle_inertia"/>
				</inertial>
				<visual>
					<geometry>
						<mesh filename="package://soft_hand_description/meshes/thumb_knuckle_left.stl" scale=" .001 .001 .001" />
					</geometry>
					<material name="SoftHand/DarkGrey" />
				</visual>
				<collision>
					<geometry>
						<mesh filename="package://soft_hand_description/meshes/thumb_knuckle_left_collision.stl" scale=" .001 .001 .001" />
					</geometry>
				</collision>
			</link>
			<gazebo reference="${name}_knuckle_link">
				<material>Gazebo/Blue</material>
			</gazebo>

			<!-- PROXIMAL PHALANGE -->
			<joint name="${name}_inner_joint" type="revolute">
				<origin xyz="0.0355 0.003300000 0.0" rpy="-0.426627741408745 0 0.0" />
				<parent link="${name}_knuckle_link"/>
				<child link="${name}_proximal_link"/>
				<axis xyz="0 -1 0" />
				<limit lower="${inner_lb *pi/180}" upper="${inner_ub *pi/180}" effort="${effort}" velocity="${velocity}"/>
				<dynamics damping="${damping}" friction="${friction}"/>
			</joint>
		</xacro:if>
		<xacro:unless value="${left}">
			<!-- KNUCKLE -->
			<joint name="${name}_abd_joint" type="revolute">
				<origin xyz="${position}" rpy="${orientation}" />
				<parent link="${parent}"/>
				<child link="${name}_knuckle_link"/>
				<axis xyz="0 0 -1" />
				<limit lower="${thumb_abd_lb *pi/180}" upper="${thumb_abd_ub *pi/180}" effort="${effort}" velocity="${velocity}"/>
				<dynamics damping="${damping}" friction="${friction}"/>
			</joint>
			
			<link name="${name}_knuckle_link">
				<inertial>
					<xacro:insert_block name="thumb_knuckle_inertia"/>
				</inertial>
				<visual>
					<geometry>
						<mesh filename="package://soft_hand_description/meshes/thumb_knuckle_right.stl" scale=" .001 .001 .001" />
					</geometry>
					<material name="SoftHand/DarkGrey" />
				</visual>
				<collision>
					<geometry>
						<mesh filename="package://soft_hand_description/meshes/thumb_knuckle_right_collision.stl" scale=" .001 .001 .001" />
					</geometry>
				</collision>
			</link>
			<gazebo reference="${name}_knuckle_link">
				<material>Gazebo/Blue</material>
			</gazebo>

			<!-- PROXIMAL PHALANGE -->
			<joint name="${name}_inner_joint" type="revolute">
				<!-- <origin xyz="0.022500000 -0.003300000 0.0" rpy="0.42662757656587236 0.0 0.18131960430075023" /> -->
				<origin xyz="0.0355 -0.003300000 0.0" rpy="0.42662757656587236 0.0 0.0"/>
				<parent link="${name}_knuckle_link"/>
				<child link="${name}_proximal_link"/>
				<axis xyz="0 -1 0" />
				<limit lower="${inner_lb *pi/180}" upper="${inner_ub *pi/180}" effort="${effort}" velocity="${velocity}"/>
				<dynamics damping="${damping}" friction="${friction}"/>
			</joint>
		</xacro:unless>

		<link name="${name}_proximal_link">
			<inertial>
				<xacro:insert_block name="phalanx_inertia"/>
			</inertial>
			<visual>
				<geometry>
					<mesh filename="package://soft_hand_description/meshes/phalanx.stl" scale=" .001 .001 .001" />
				</geometry>
				<material name="SoftHand/DarkGrey" />
			</visual>
			<collision>
				<geometry>
					<mesh filename="package://soft_hand_description/meshes/phalanx_collision.stl" scale=" .001 .001 .001" />
				</geometry>
			</collision>
		</link>
		<gazebo reference="${name}_proximal_link">
			<material>Gazebo/Blue</material>
		</gazebo>

		<!-- DISTAL PHALANGE -->
		<joint name="${name}_outer_joint" type="revolute">
			<origin xyz="0.022 0 0.0" rpy="0 0 0" />
			<parent link="${name}_proximal_link"/>
			<child link="${name}_distal_link"/>
			<axis xyz="0 -1 0" />
			<limit lower="${outer_lb *pi/180}" upper="${outer_ub *pi/180}" effort="${effort}" velocity="${velocity}"/>
			<dynamics damping="${damping}" friction="${friction}"/>
		</joint>

		<link name="${name}_distal_link">
			<inertial>
				<xacro:insert_block name="fingertip_inertia"/>
			</inertial>
			<visual>
				<geometry>
					<mesh filename="package://soft_hand_description/meshes/fingertip.stl" scale=" .001 .001 .001" />
				</geometry>
				<material name="SoftHand/DarkGrey" />
			</visual>
			<collision>
				<geometry>
					<mesh filename="package://soft_hand_description/meshes/fingertip_collision.stl" scale=" .001 .001 .001" />
				</geometry>
			</collision>
		</link>
		<gazebo reference="${name}_distal_link">
			<selfCollide>false</selfCollide>
			<mu1>${rubber_friction_coefficient}</mu1>
			<mu2>${rubber_friction_coefficient}</mu2>
			<kp>${rubber_contact_stiffness_coefficient}</kp>
			<kd>${rubber_contact_damping_coefficient}</kd>
			<material>Gazebo/Blue</material>
		</gazebo>
	</xacro:macro>

	<!-- SOFT HAND MODEL -->
	<xacro:macro name="soft_hand" params="parent name withAdaptiveTransmission left *origin">

		<!-- PACMAN VERION ALREADY INCLUDES THE COUPLER, CLAMP AND BASE -->

		<!-- KUKA_COUPLER -->
		<xacro:kuka_coupler parent="${parent}" name="${name}_kuka_coupler">
			<xacro:insert_block name="origin"/>
		</xacro:kuka_coupler>

		<!-- CLAMP -->
		<xacro:clamp parent="${name}_kuka_coupler" name="${name}_clamp">
			<origin xyz="0 0 0.01" rpy="0 0 0"/>
		</xacro:clamp>
		<gazebo reference="${name}_kuka_coupler">
			<material>Gazebo/Gold</material>
		</gazebo>

		<!-- SOFT HAND BASE -->
		<xacro:softhand_base parent="${name}_clamp" name="${name}_softhand_base" left="${left}">
			<origin xyz="0 0 0.004" rpy="0 0 0"/>
		</xacro:softhand_base>
		<gazebo reference="${name}_softhand_base">
			<material>Gazebo/Gold</material>
		</gazebo>

		<!-- PALM -->
		<joint name="${name}_palm_joint" type="fixed">
			<xacro:if value="${left}">
				<origin xyz="0.002 -0.00695 0.0535" rpy="0 0 0"/>
			</xacro:if>
			<xacro:unless value="${left}">
				<origin xyz="0.002 0.00695 0.0535" rpy="0 0 0"/>
			</xacro:unless>
			<parent link="${name}_softhand_base" />
			<child link="${name}_palm_link" />
		</joint>

		<link name="${name}_palm_link">
			<inertial>
				<xacro:insert_block name="palm_inertia"/>
			</inertial>
			<xacro:if value="${left}">
				<visual>
					<geometry>
						<mesh filename="package://soft_hand_description/meshes/palm_left.stl" scale=" .001 .001 .001" />
					</geometry>
					<material name="SoftHand/DarkGrey" />
				</visual>
				<collision>
					<geometry>
						<mesh filename="package://soft_hand_description/meshes/palm_left_collision.stl" scale=" .001 .001 .001" />
					</geometry>
				</collision>
			</xacro:if>
			<xacro:unless value="${left}">
				<visual>
					<geometry>
						<mesh filename="package://soft_hand_description/meshes/palm_right.stl" scale=" .001 .001 .001" />
					</geometry>
					<material name="SoftHand/DarkGrey" />
				</visual>
				<collision>
					<geometry>
						<mesh filename="package://soft_hand_description/meshes/palm_right_collision.stl" scale=" .001 .001 .001" />
					</geometry>
				</collision>
			</xacro:unless>
		</link>
		<gazebo reference="${name}_palm_link">
			<material>Gazebo/White</material>
		</gazebo>
		

		<!-- THUMB AND FINGERS -->
		<!-- change anchor points accordingly to the leftness -->
		<xacro:if value="${left}"> 
			<xacro:soft_thumb parent="${name}_palm_link" parent_name="${name}" name="${name}_thumb" position="0.005669722 -0.029616 0.055314" orientation="0.0 -0.38397275793662144 -1.5707963267948966" left="${left}"/>

			<xacro:soft_finger parent="${name}_palm_link" parent_name="${name}" name="${name}_index" position="-0.0033 -0.0195 0.0936994" orientation="-1.5707963267948966 -1.4835299330931884 -1.5707963267948966" left="${left}"/>

			<xacro:soft_finger parent="${name}_palm_link" parent_name="${name}" name="${name}_middle" position="-0.0033 0.0 0.100699" orientation="3.1415 -1.5707963267948966 0.0" left="${left}"/>

			<xacro:soft_finger parent="${name}_palm_link" parent_name="${name}" name="${name}_ring" position="-0.0033 0.0195 0.0936994" orientation="1.5707963267948966 -1.5184364298870514 1.5707963267948966" left="${left}"/>

			<xacro:soft_finger parent="${name}_palm_link" parent_name="${name}" name="${name}_little" position="-0.0033 0.039 0.0836994" orientation="1.5707963267948966 -1.4835299330931884 1.5707963267948966" left="${left}"/>
		</xacro:if>
		<xacro:unless value="${left}">
			<xacro:soft_thumb parent="${name}_palm_link" parent_name="${name}" name="${name}_thumb" position="0.00566972 0.0296160 0.0553140" orientation="0.0 -0.38397275793662144 1.5707963267948966" left="${left}"/>

			<xacro:soft_finger parent="${name}_palm_link" parent_name="${name}" name="${name}_index" position="-0.0033 0.0195 0.0936994" orientation="1.5707963267948966 -1.4835299330931884 1.5707963267948966" left="${left}"/>

			<xacro:soft_finger parent="${name}_palm_link" parent_name="${name}" name="${name}_middle" position="-0.003300000 0.0 0.100699" orientation="3.141592 -1.5707963267948966 0.0" left="${left}"/>

			<xacro:soft_finger parent="${name}_palm_link" parent_name="${name}" name="${name}_ring" position="-0.0033 -0.0195 0.0936994" orientation="-1.5707963267948966 -1.5184364298870514 -1.5707963267948966 " left="${left}" />

			<xacro:soft_finger parent="${name}_palm_link" parent_name="${name}" name="${name}_little" position="-0.0033 -0.039 0.0836994" orientation="-1.5707963267948966 -1.4835299330931884 -1.5707963267948966" left="${left}"/>
		</xacro:unless>

		<xacro:soft_hand_transmission name="${name}" withAdaptiveTransmission="${withAdaptiveTransmission}"/>
		<xacro:soft_hand_gazebo name="${name}" withAdaptiveTransmission="${withAdaptiveTransmission}"/>
		
	</xacro:macro>

</robot>